<?xml version="1.0" ?>
<!-- =================================================================================== -->
<!-- |    This document was autogenerated by xacro from inail2arm.urdf.xacro           | -->
<!-- |    EDITING THIS FILE BY HAND IS NOT RECOMMENDED                                 | -->
<!-- =================================================================================== -->
<robot name="inail2arm">
  <material name="grey">
    <color rgba="0.5 0.5 0.5 1"/>
  </material>
  <material name="dark_grey">
    <color rgba="0.3 0.3 0.3 1"/>
  </material>
  <material name="red">
    <color rgba="1.0 0.0 0.0 1"/>
  </material>
  <material name="green">
    <color rgba="0.0 1.0 0.0 1"/>
  </material>
  <material name="blue">
    <color rgba="0.13333333333333333 0.25882352941176473 0.7803921568627451 1.0"/>
  </material>
  <!-- /macro arms -->
  <!-- /macro ee -->
  <!-- Origin -->
  <!-- base -->
  <link name="dummy">
   </link>
  <link name="base_link">
    <inertial>
      <origin xyz="0.00020548930000000002 -0.00062095789 0.077352002"/>
      <mass value="2.7764953"/>
      <inertia ixx="0.010002127" ixy="4.1468013999999995e-05" ixz="-5.1253649e-05" iyy="0.010728527" iyz="-0.00012700723" izz="0.006215603699999999"/>
    </inertial>
    <visual>
      <origin rpy="0.0 0.0 0.0" xyz="0.0 0.0 0.0"/>
      <geometry>
        <mesh filename="package://inail2arm_urdf/meshes/mesh_base.stl" scale="0.001 0.001 0.001"/>
      </geometry>
      <material name="dark_grey"/>
    </visual>
    <collision>
      <origin rpy="0.0 0.0 0.0" xyz="0.0 0.0 0.0"/>
      <geometry>
        <mesh filename="package://inail2arm_urdf/meshes/simple/mesh_base.stl" scale="0.001 0.001 0.001"/>
      </geometry>
    </collision>
  </link>
  <!-- base -->
  <!-- Screws mounting points -->
  <link name="screw_top_right"/>
  <link name="screw_top_left"/>
  <link name="screw_bottom_right"/>
  <link name="screw_bottom_left"/>
  <joint name="screw_top_right_joint" type="fixed">
    <parent link="base_link"/>
    <child link="screw_top_right"/>
    <origin rpy="0 0 0" xyz="0.05 -0.05 0"/>
  </joint>
  <joint name="screw_top_left_joint" type="fixed">
    <parent link="base_link"/>
    <child link="screw_top_left"/>
    <origin rpy="0 0 0" xyz="0.05 0.05 0"/>
  </joint>
  <joint name="screw_bottom_right_joint" type="fixed">
    <parent link="base_link"/>
    <child link="screw_bottom_right"/>
    <origin rpy="0 0 0" xyz="-0.05 -0.05 0"/>
  </joint>
  <joint name="screw_bottom_left_joint" type="fixed">
    <parent link="base_link"/>
    <child link="screw_bottom_left"/>
    <origin rpy="0 0 0" xyz="-0.05 0.05 0"/>
  </joint>
  <!-- Screws mounting point -->
  <!-- LINKS -->
  <!-- shoulder yaw-->
  <link name="arm1_1">
    <inertial>
      <origin xyz="8.4798664e-05 -0.020782662 0.032183554999999996"/>
      <mass value="0.41054046"/>
      <inertia ixx="0.0012949444" ixy="-1.8773371e-06" ixz="1.2479427999999998e-06" iyy="0.0012303834999999998" iyz="0.00032390228999999997" izz="0.0008036788199999999"/>
    </inertial>
    <visual>
      <origin rpy="0.0 0.0 0.0" xyz="0.0 0.0 0.0"/>
      <geometry>
        <mesh filename="package://inail2arm_urdf/meshes/mesh_shoulder-yaw.stl" scale="0.001 0.001 0.001"/>
      </geometry>
      <material name="blue"/>
    </visual>
    <collision>
      <origin rpy="0.0 0.0 0.0" xyz="0.0 0.0 0.0"/>
      <geometry>
        <mesh filename="package://inail2arm_urdf/meshes/simple/mesh_shoulder-yaw.stl" scale="0.001 0.001 0.001"/>
      </geometry>
    </collision>
  </link>
  <!-- shoulder yaw-->
  <!-- shoulder pitch-->
  <link name="arm1_2">
    <inertial>
      <origin xyz="-3.636067e-05 0.16072685 -0.062849027"/>
      <mass value="3.2487988"/>
      <inertia ixx="0.090371217" ixy="9.791527499999999e-05" ixz="-5.558155099999999e-06" iyy="0.0065574254" iyz="-0.0029068254" izz="0.088276594"/>
    </inertial>
    <visual>
      <origin rpy="0.0 0.0 0.0" xyz="0.0 0.0 0.0"/>
      <geometry>
        <mesh filename="package://inail2arm_urdf/meshes/mesh_shoulder-pitch.stl" scale="0.001 0.001 0.001"/>
      </geometry>
      <material name="blue"/>
    </visual>
    <collision>
      <origin rpy="0.0 0.0 0.0" xyz="0.0 0.0 0.0"/>
      <geometry>
        <mesh filename="package://inail2arm_urdf/meshes/simple/mesh_shoulder-pitch.stl" scale="0.001 0.001 0.001"/>
      </geometry>
    </collision>
  </link>
  <!-- shoulder pitch-->
  <!-- elbow-yaw-->
  <link name="arm1_3">
    <inertial>
      <origin xyz="-1.2974906e-05 0.064319293 -0.03429615"/>
      <mass value="0.52461209"/>
      <inertia ixx="0.0015799731999999998" ixy="3.0297811e-07" ixz="4.1461879e-07" iyy="0.0010025017999999999" iyz="0.00038387214" izz="0.0014999643"/>
    </inertial>
    <visual>
      <origin rpy="0.0 0.0 0.0" xyz="0.0 0.0 0.0"/>
      <geometry>
        <mesh filename="package://inail2arm_urdf/meshes/mesh_elbow.stl" scale="0.001 0.001 0.001"/>
      </geometry>
      <material name="blue"/>
    </visual>
    <collision>
      <origin rpy="0.0 0.0 0.0" xyz="0.0 0.0 0.0"/>
      <geometry>
        <mesh filename="package://inail2arm_urdf/meshes/simple/mesh_elbow.stl" scale="0.001 0.001 0.001"/>
      </geometry>
    </collision>
  </link>
  <!-- elbow-yaw-->
  <!-- forearm-yaw -->
  <link name="arm1_4">
    <inertial>
      <origin xyz="-6.452875299999999e-05 -0.046448856999999996 0.13357443000000002"/>
      <mass value="2.0046544"/>
      <inertia ixx="0.023326476999999998" ixy="-1.7237335e-05" ixz="-2.9785178999999997e-05" iyy="0.02013323" iyz="0.006970601399999999" izz="0.0052212805"/>
    </inertial>
    <visual>
      <origin rpy="0.0 0.0 0.0" xyz="0.0 0.0 0.0"/>
      <geometry>
        <mesh filename="package://inail2arm_urdf/meshes/mesh_forearm-yaw.stl" scale="0.001 0.001 0.001"/>
      </geometry>
      <material name="blue"/>
    </visual>
    <collision>
      <origin rpy="0.0 0.0 0.0" xyz="0.0 0.0 0.0"/>
      <geometry>
        <mesh filename="package://inail2arm_urdf/meshes/simple/mesh_forearm-yaw.stl" scale="0.001 0.001 0.001"/>
      </geometry>
    </collision>
  </link>
  <!-- forearm-yaw -->
  <!--wrist-pitch -->
  <link name="arm1_5">
    <inertial>
      <origin xyz="-4.7450211e-05 0.017403047999999997 0.040478983999999996"/>
      <mass value="1.0418416"/>
      <inertia ixx="0.0018450264" ixy="-6.3813838e-07" ixz="1.6212593e-05" iyy="0.0011114155" iyz="-3.7623514e-05" izz="0.0018417393"/>
    </inertial>
    <visual>
      <origin rpy="0.0 0.0 0.0" xyz="0.0 0.0 0.0"/>
      <geometry>
        <mesh filename="package://inail2arm_urdf/meshes/mesh_wrist-pitch.stl" scale="0.001                0.001 0.001"/>
      </geometry>
      <material name="blue"/>
    </visual>
    <collision>
      <origin rpy="0.0 0.0 0.0" xyz="0.0 0.0 0.0"/>
      <geometry>
        <mesh filename="package://inail2arm_urdf/meshes/simple/mesh_wrist-pitch.stl" scale="0.001                0.001 0.001"/>
      </geometry>
    </collision>
  </link>
  <link name="arm1_6">
    <inertial>
      <origin xyz="0 0 0"/>
      <mass value="0.001"/>
      <inertia ixx="0.0001" ixy="0" ixz="0" iyy="0.0001" iyz="0" izz="0.0001"/>
    </inertial>
    <!-- <visual>
            <origin xyz="0.0 0.0 0.0" rpy="0.0 0.0 0.0" />
            <geometry>
               <mesh
                  filename="package://inail2arm_urdf/meshes/mesh_wrist-pitch.stl"
                  scale="0.001
               ${rot*0.001} 0.001" />
            </geometry>
            <material name="blue" />
         </visual>

         <collision>
            <origin xyz="0.0 0.0 0.0" rpy="0.0 0.0 0.0" />
            <geometry>
               <mesh
                  filename="package://inail2arm_urdf/meshes/simple/mesh_wrist-pitch.stl"
                  scale="0.001
               ${rot*0.001} 0.001" />
            </geometry>
         </collision> -->
  </link>
  <!--wrist-pitch -->
  <!-- /LINKS -->
  <!-- JOINTS -->
  <!-- shoulder yaw -->
  <joint name="dummy_joint" type="fixed">
    <parent link="dummy"/>
    <child link="base_link"/>
  </joint>
  <joint name="j_arm1_1" type="revolute">
    <parent link="base_link"/>
    <child link="arm1_1"/>
    <axis xyz="0 0 1"/>
    <origin rpy="0.0 0.0 0.0" xyz="0.0 0.0 0.17515"/>
    <limit effort="147.0" lower="-2.85" upper="2.85" velocity="3.86"/>
  </joint>
  <!-- shoulder yaw -->
  <!-- shoulder pitch -->
  <joint name="j_arm1_2" type="revolute">
    <parent link="arm1_1"/>
    <child link="arm1_2"/>
    <origin rpy="1.570796326795 0.0 0.0" xyz="0.0 -0.051 0.079"/>
    <axis xyz="0 0 -1"/>
    <limit effort="147.0" lower="-2.0" upper="2.0" velocity="3.86"/>
  </joint>
  <!-- shoulder pitch -->
  <!-- elbow yaw -->
  <joint name="j_arm1_3" type="revolute">
    <parent link="arm1_2"/>
    <child link="arm1_3"/>
    <origin rpy="0.0 0.0 0.0" xyz="0.0 0.365095 0.0"/>
    <axis xyz="0 0 1"/>
    <limit effort="147.0" lower="-2.2" upper="2.2" velocity="6.06"/>
  </joint>
  <!-- elbow yaw -->
  <!-- forearm yaw -->
  <joint name="j_arm1_4" type="revolute">
    <parent link="arm1_3"/>
    <child link="arm1_4"/>
    <origin rpy="-1.570796326795 0.0 0.0" xyz="0.0 0.0825 -0.051"/>
    <axis xyz="0 0 1"/>
    <limit effort="147.0" lower="-2.7" upper="2.7" velocity="6.06"/>
  </joint>
  <!-- forearm yaw -->
  <!-- wrist pitch-->
  <joint name="j_arm1_5" type="revolute">
    <parent link="arm1_4"/>
    <child link="arm1_5"/>
    <origin rpy="-1.570796326795 0.0 0.0" xyz="0.0 -0.043 0.2525"/>
    <axis xyz="0 0 1"/>
    <limit effort="55.0" lower="-2.2" upper="2.2" velocity="11.72"/>
  </joint>
  <!-- wrist pitch-->
  <!-- wrist2 pitch-->
  <joint name="j_arm1_6" type="revolute">
    <parent link="arm1_5"/>
    <child link="arm1_6"/>
    <origin rpy="0 0.0 0.0" xyz="0.0 -0.02 0.043"/>
    <axis xyz="0 1 0"/>
    <limit effort="55.0" lower="-2.85" upper="2.85" velocity="11.72"/>
  </joint>
  <!-- /wrist2 pitch-->
  <joint name="dagana_1_mount_joint" type="fixed">
    <origin rpy="1.570796326795 0 0" xyz="0 -0.018 0"/>
    <parent link="arm1_6"/>
    <child link="dagana_1_top_link"/>
  </joint>
  <link name="dagana_1_top_link">
    <inertial>
      <origin rpy="0 0 0" xyz="-0.0063562154 -0.0060265532000000005  0.060068288000000004"/>
      <mass value="1.7432400"/>
      <inertia ixx="0.0050510328" ixy="-0.00025264216" ixz="-0.00012103013" iyy="0.0047944612" iyz="-0.00073917704" izz="0.0031156997"/>
    </inertial>
    <visual>
      <origin rpy="0 0 0" xyz="0 0 0"/>
      <geometry>
        <mesh filename="package://dagana_urdf/meshes/dg0001-simplified.stl" scale="0.001 0.001 0.001"/>
      </geometry>
      <material name="dark_grey"/>
    </visual>
    <collision>
      <origin rpy="0 0 0" xyz="0 0 0"/>
      <geometry>
        <mesh filename="package://dagana_urdf/meshes/dg0001-simplified.stl" scale="0.001 0.001 0.001"/>
      </geometry>
      <material name="dark_grey"/>
    </collision>
  </link>
  <joint name="dagana_1_claw_joint" type="fixed">
    <origin rpy="1.57079632679 0 3.14159265359" xyz="0.0 -0.028 0.05025"/>
    <parent link="dagana_1_top_link"/>
    <child link="dagana_1_bottom_link"/>
    <axis xyz="-1 0 0"/>
    <limit effort="1000" lower="0" upper="1" velocity="2.0"/>
  </joint>
  <link name="dagana_1_bottom_link">
    <inertial>
      <origin rpy="0 0 0" xyz="0 0.069644767 0"/>
      <mass value="4.6117745e-01"/>
      <inertia ixx="0.0014726990999999999" ixy="7.134683e-05" ixz="2.529065e-06" iyy="0.0009385556899999999" iyz="-0.000264452" izz="0.0019472731"/>
    </inertial>
    <visual>
      <origin rpy="0 0 0" xyz="0 0 0"/>
      <geometry>
        <mesh filename="package://dagana_urdf/meshes/dg0002.stl" scale="0.001 0.001 0.001"/>
      </geometry>
      <material name="dark_grey"/>
    </visual>
    <collision>
      <origin rpy="0 0 0" xyz="0 0 0"/>
      <geometry>
        <mesh filename="package://dagana_urdf/meshes/dg0002-ch.stl" scale="0.001 0.001 0.001"/>
      </geometry>
      <material name="dark_grey"/>
    </collision>
  </link>
  <!-- Manually put to have a transform in a "good" grasping spot-->
  <joint name="dagana_1_tcp_joint" type="fixed">
    <origin rpy="0 0 0" xyz="0 -0.05 0.15"/>
    <parent link="dagana_1_top_link"/>
    <child link="dagana_1_tcp"/>
  </joint>
  <link name="dagana_1_tcp"/>
  <!--     to have the same final link as when "none" option is used     -->
  <link name="tcp_1"/>
  <joint name="j_tcp_1" type="fixed">
    <parent link="dagana_1_tcp"/>
    <child link="tcp_1"/>
    <origin rpy="0 0 0" xyz="0 0 0"/>
  </joint>
  <!-- Proximity Sensors -->
  <link name="teraflex_1_sensor1_link"/>
  <link name="teraflex_1_sensor2_link"/>
  <link name="teraflex_1_sensor3_link"/>
  <link name="teraflex_1_sensor4_link"/>
  <link name="teraflex_1_sensor5_link"/>
  <link name="teraflex_1_sensor6_link"/>
  <!-- joint fake -->
  <joint name="teraflex_1_sensor0_joint" type="fixed">
    <!-- sensor 1 -->
    <parent link="arm1_4"/>
    <child link="teraflex_1_sensor1_link"/>
    <origin rpy="-3.1416 0.0 0.0" xyz="0.05460 -0.069500 0.0599528"/>
  </joint>
  <!-- joint fake -->
  <joint name="teraflex_1_sensor1_joint" type="fixed">
    <!-- sensor 2 -->
    <parent link="arm1_4"/>
    <child link="teraflex_1_sensor2_link"/>
    <origin rpy="3.1416 0.0 -1.5708" xyz="0.00 -0.112600 0.0599528"/>
  </joint>
  <!-- joint fake -->
  <joint name="teraflex_1_sensor2_joint" type="fixed">
    <!-- sensor 3 -->
    <parent link="arm1_4"/>
    <child link="teraflex_1_sensor3_link"/>
    <origin rpy="3.1416 0.0 3.1416" xyz="-0.05460 -0.069500 0.0599528"/>
  </joint>
  <!-- joint fake -->
  <joint name="teraflex_1_sensor3_joint" type="fixed">
    <!-- sensor 4 -->
    <parent link="arm1_4"/>
    <child link="teraflex_1_sensor4_link"/>
    <origin rpy="3.1416 0.0 0.0" xyz="0.05460 -0.1100 0.22920"/>
  </joint>
  <!-- joint fake -->
  <joint name="teraflex_1_sensor4_joint" type="fixed">
    <!-- sensor 5 -->
    <parent link="arm1_4"/>
    <child link="teraflex_1_sensor5_link"/>
    <origin rpy="3.1416 0.0 -1.5708" xyz="0.0 -0.133600 0.22920"/>
  </joint>
  <!-- joint fake -->
  <joint name="teraflex_1_sensor5_joint" type="fixed">
    <!-- sensor 6 -->
    <parent link="arm1_4"/>
    <child link="teraflex_1_sensor6_link"/>
    <origin rpy="3.1416 0.0 3.1416" xyz="-0.05460 -0.1100 0.22920"/>
  </joint>
  <!-- Proximity Sensors END-->
</robot>
